Workbook
Name Orders: Orders!$A$1:$U$9995
Name People: People!$A$1:$B$5
Name Returns: Returns!$A$1:$A$801

Sheet Dashboard
D2: Superstore - Dashboard
D3: Total sales: | E3: 2297200.9
D4: Total profit: | E4: 286397.02
D5: Profit Ratio: | E5: =E4/E3 -> 0.12467217
D6: Profit per Order: | E6: =E4/Data[[#Totals],[Order ID]] -> 57.176487
D7: Sales per Customer: | E7: =E3/568 -> 4044.3677

Sheet Выводы
A1: Раздел | B1: Содержание
A2: Аналитическая оценка
A3: Рекомендации

Sheet Orders
A1: Row ID | B1: Order ID | C1: Order Date | D1: Ship Date | E1: Ship Mode | F1: Customer ID | G1: Customer Name | H1: Segment | I1: Country | J1: City | K1: State | L1: Postal Code | M1: Region | N1: Product ID | O1: Category | P1: Sub-Category | Q1: Product Name | R1: Sales | S1: Quantity | T1: Discount | U1: Profit | V1: Person | W1: Returned
A2: 1 | B2: CA-2018-152156 | C2: 43412 | D2: 43415 | E2: Second Class | F2: CG-12520 | G2: Claire Gute | H2: Consumer | I2: United States | J2: Henderson | K2: Kentucky | L2: 42420 | M2: South | N2: FUR-BO-10001798 | O2: Furniture | P2: Bookcases | Q2: Bush Somerset Collection Bookcase | R2: 261.96 | S2: 2 | T2: 0 | U2: 41.9136 | V2: =IF(M2=People!$B$5,People!$A$5,IF(M2=People!$B$4,People!$A$4,IF(M2=People!$B$3,People!$A$3,IF(M2=People!$B$2,People!$A$2,0)))) -> Cassandra Brandow | W2: =IFERROR(INDEX(Returns!A:A,MATCH(B2,Returns!B:B,0)),"No") -> No
A3: 2 | B3: CA-2018-152156 | C3: 43412 | D3: 43415 | E3: Second Class | F3: CG-12520 | G3: Claire Gute | H3: Consumer | I3: United States | J3: Henderson | K3: Kentucky | L3: 42420 | M3: South | N3: FUR-CH-10000454 | O3: Furniture | P3: Chairs | Q3: Hon Deluxe Fabric Upholstered Stacking Chairs, Rounded Back | R3: 731.94 | S3: 3 | T3: 0 | U3: 219.582 | V3: =IF(M3=People!$B$5,People!$A$5,IF(M3=People!$B$4,People!$A$4,IF(M3=People!$B$3,People!$A$3,IF(M3=People!$B$2,People!$A$2,0)))) -> Cassandra Brandow | W3: =IFERROR(INDEX(Returns!A:A,MATCH(B3,Returns!B:B,0)),"No") -> No
A4: 3 | B4: CA-2018-138688 | C4: 43263 | D4: 43267 | E4: Second Class | F4: DV-13045 | G4: Darrin Van Huff | H4: Corporate | I4: United States | J4: Los Angeles | K4: California | L4: 90036 | M4: West | N4: OFF-LA-10000240 | O4: Office Supplies | P4: Labels | Q4: Self-Adhesive Address Labels for Typewriters by Universal | R4: 14.62 | S4: 2 | T4: 0 | U4: 6.8714 | V4: =IF(M4=People!$B$5,People!$A$5,IF(M4=People!$B$4,People!$A$4,IF(M4=People!$B$3,People!$A$3,IF(M4=People!$B$2,People!$A$2,0)))) -> Anna Andreadi | W4: =IFERROR(INDEX(Returns!A:A,MATCH(B4,Returns!B:B,0)),"No") -> No
A5: 4 | B5: US-2017-108966 | C5: 43019 | D5: 43026 | E5: Standard Class | F5: SO-20335 | G5: Sean O'Donnell | H5: Consumer | I5: United States | J5: Fort Lauderdale | K5: Florida | L5: 33311 | M5: South | N5: FUR-TA-10000577 | O5: Furniture | P5: Tables | Q5: Bretford CR4500 Series Slim Rectangular Table | R5: 957.5775 | S5: 5 | T5: 0.45 | U5: -383.031 | V5: =IF(M5=People!$B$5,People!$A$5,IF(M5=People!$B$4,People!$A$4,IF(M5=People!$B$3,People!$A$3,IF(M5=People!$B$2,People!$A$2,0)))) -> Cassandra Brandow | W5: =IFERROR(INDEX(Returns!A:A,MATCH(B5,Returns!B:B,0)),"No") -> No
A6: 5 | B6: US-2017-108966 | C6: 43019 | D6: 43026 | E6: Standard Class | F6: SO-20335 | G6: Sean O'Donnell | H6: Consumer | I6: United States | J6: Fort Lauderdale | K6: Florida | L6: 33311 | M6: South | N6: OFF-ST-10000760 | O6: Office Supplies | P6: Storage | Q6: Eldon Fold 'N Roll Cart System | R6: 22.368 | S6: 2 | T6: 0.2 | U6: 2.5164 | V6: =IF(M6=People!$B$5,People!$A$5,IF(M6=People!$B$4,People!$A$4,IF(M6=People!$B$3,People!$A$3,IF(M6=People!$B$2,People!$A$2,0)))) -> Cassandra Brandow | W6: =IFERROR(INDEX(Returns!A:A,MATCH(B6,Returns!B:B,0)),"No") -> No
A7: 6 | B7: CA-2016-115812 | C7: 42530 | D7: 42535 | E7: Standard Class | F7: BH-11710 | G7: Brosina Hoffman | H7: Consumer | I7: United States | J7: Los Angeles | K7: California | L7: 90032 | M7: West | N7: FUR-FU-10001487 | O7: Furniture | P7: Furnishings | Q7: Eldon Expressions Wood and Plastic Desk Accessories, Cherry Wood | R7: 48.86 | S7: 7 | T7: 0 | U7: 14.1694 | V7: =IF(M7=People!$B$5,People!$A$5,IF(M7=People!$B$4,People!$A$4,IF(M7=People!$B$3,People!$A$3,IF(M7=People!$B$2,People!$A$2,0)))) -> Anna Andreadi | W7: =IFERROR(INDEX(Returns!A:A,MATCH(B7,Returns!B:B,0)),"No") -> No
A8: 7 | B8: CA-2016-115812 | C8: 42530 | D8: 42535 | E8: Standard Class | F8: BH-11710 | G8: Brosina Hoffman | H8: Consumer | I8: United States | J8: Los Angeles | K8: California | L8: 90032 | M8: West | N8: OFF-AR-10002833 | O8: Office Supplies | P8: Art | Q8: Newell 322 | R8: 7.28 | S8: 4 | T8: 0 | U8: 1.9656 | V8: =IF(M8=People!$B$5,People!$A$5,IF(M8=People!$B$4,People!$A$4,IF(M8=People!$B$3,People!$A$3,IF(M8=People!$B$2,People!$A$2,0)))) -> Anna Andreadi | W8: =IFERROR(INDEX(Returns!A:A,MATCH(B8,Returns!B:B,0)),"No") -> No
A9: 8 | B9: CA-2016-115812 | C9: 42530 | D9: 42535 | E9: Standard Class | F9: BH-11710 | G9: Brosina Hoffman | H9: Consumer | I9: United States | J9: Los Angeles | K9: California | L9: 90032 | M9: West | N9: TEC-PH-10002275 | O9: Technology | P9: Phones | Q9: Mitel 5320 IP Phone VoIP phone | R9: 907.152 | S9: 6 | T9: 0.2 | U9: 90.7152 | V9: =IF(M9=People!$B$5,People!$A$5,IF(M9=People!$B$4,People!$A$4,IF(M9=People!$B$3,People!$A$3,IF(M9=People!$B$2,People!$A$2,0)))) -> Anna Andreadi | W9: =IFERROR(INDEX(Returns!A:A,MATCH(B9,Returns!B:B,0)),"No") -> No
A10: 9 | B10: CA-2016-115812 | C10: 42530 | D10: 42535 | E10: Standard Class | F10: BH-11710 | G10: Brosina Hoffman | H10: Consumer | I10: United States | J10: Los Angeles | K10: California | L10: 90032 | M10: West | N10: OFF-BI-10003910 | O10: Office Supplies | P10: Binders | Q10: DXL Angle-View Binders with Locking Rings by Samsill | R10: 18.504 | S10: 3 | T10: 0.2 | U10: 5.7825 | V10: =IF(M10=People!$B$5,People!$A$5,IF(M10=People!$B$4,People!$A$4,IF(M10=People!$B$3,People!$A$3,IF(M10=People!$B$2,People!$A$2,0)))) -> Anna Andreadi | W10: =IFERROR(INDEX(Returns!A:A,MATCH(B10,Returns!B:B,0)),"No") -> No
A11: 10 | B11: CA-2016-115812 | C11: 42530 | D11: 42535 | E11: Standard Class | F11: BH-11710 | G11: Brosina Hoffman | H11: Consumer | I11: United States | J11: Los Angeles | K11: California | L11: 90032 | M11: West | N11: OFF-AP-10002892 | O11: Office Supplies | P11: Appliances | Q11: Belkin F5C206VTEL 6 Outlet Surge | R11: 114.9 | S11: 5 | T11: 0 | U11: 34.47 | V11: =IF(M11=People!$B$5,People!$A$5,IF(M11=People!$B$4,People!$A$4,IF(M11=People!$B$3,People!$A$3,IF(M11=People!$B$2,People!$A$2,0)))) -> Anna Andreadi | W11: =IFERROR(INDEX(Returns!A:A,MATCH(B11,Returns!B:B,0)),"No") -> No
A12: 11 | B12: CA-2016-115812 | C12: 42530 | D12: 42535 | E12: Standard Class | F12: BH-11710 | G12: Brosina Hoffman | H12: Consumer | I12: United States | J12: Los Angeles | K12: California | L12: 90032 | M12: West | N12: FUR-TA-10001539 | O12: Furniture | P12: Tables | Q12: Chromcraft Rectangular Conference Tables | R12: 1706.184 | S12: 9 | T12: 0.2 | U12: 85.3092 | V12: =IF(M12=People!$B$5,People!$A$5,IF(M12=People!$B$4,People!$A$4,IF(M12=People!$B$3,People!$A$3,IF(M12=People!$B$2,People!$A$2,0)))) -> Anna Andreadi | W12: =IFERROR(INDEX(Returns!A:A,MATCH(B12,Returns!B:B,0)),"No") -> No
A13: 12 | B13: CA-2016-115812 | C13: 42530 | D13: 42535 | E13: Standard Class | F13: BH-11710 | G13: Brosina Hoffman | H13: Consumer | I13: United States | J13: Los Angeles | K13: California | L13: 90032 | M13: West | N13: TEC-PH-10002033 | O13: Technology | P13: Phones | Q13: Konftel 250 Conference phone - Charcoal black | R13: 911.424 | S13: 4 | T13: 0.2 | U13: 68.3568 | V13: =IF(M13=People!$B$5,People!$A$5,IF(M13=People!$B$4,People!$A$4,IF(M13=People!$B$3,People!$A$3,IF(M13=People!$B$2,People!$A$2,0)))) -> Anna Andreadi | W13: =IFERROR(INDEX(Returns!A:A,MATCH(B13,Returns!B:B,0)),"No") -> No
... A2235: 2234 | B2235: CA-2017-123232 | C2235: 43083 | D2235: 43085 | E2235: Second Class | F2235: DJ-13630 | G2235: Doug Jacobs | H2235: Consumer | I2235: United States | J2235: Portland | K2235: Oregon | L2235: 97206 | M2235: West | N2235: TEC-PH-10001051 | O2235: Technology | P2235: Phones | Q2235: HTC One | R2235: 319.968 | S2235: 4 | T2235: 0.2 | U2235: 35.9964 | V2235: =IF(M2235=People!$B$5,People!$A$5,IF(M2235=People!$B$4,People!$A$4,IF(M2235=People!$B$3,People!$A$3,IF(M2235=People!$B$2,People!$A$2,0)))) -> Anna Andreadi | W2235: =IFERROR(INDEX(Returns!A:A,MATCH(B2235,Returns!B:B,0)),"No") -> No
A2236: 2235 | B2236: CA-2019-104066 | C2236: 43804 | D2236: 43809 | E2236: Standard Class | F2236: QJ-19255 | G2236: Quincy Jones | H2236: Corporate | I2236: United States | J2236: Burlington | K2236: Vermont | M2236: East | N2236: TEC-AC-10001013 | O2236: Technology | P2236: Accessories | Q2236: Logitech ClearChat Comfort/USB Headset H390 | R2236: 205.03 | S2236: 7 | T2236: 0 | U2236: 67.6599 | V2236: =IF(M2236=People!$B$5,People!$A$5,IF(M2236=People!$B$4,People!$A$4,IF(M2236=People!$B$3,People!$A$3,IF(M2236=People!$B$2,People!$A$2,0)))) -> Chuck Magee | W2236: =IFERROR(INDEX(Returns!A:A,MATCH(B2236,Returns!B:B,0)),"No") -> No
A2237: 2236 | B2237: CA-2017-145849 | C2237: 42993 | D2237: 42995 | E2237: Second Class | F2237: CT-11995 | G2237: Carol Triggs | H2237: Consumer | I2237: United States | J2237: Indianapolis | K2237: Indiana | L2237: 46203 | M2237: Central | N2237: OFF-ST-10000025 | O2237: Office Supplies | P2237: Storage | Q2237: Fellowes Stor/Drawer Steel Plus Storage Drawers | R2237: 190.86 | S2237: 2 | T2237: 0 | U2237: 11.4516 | V2237: =IF(M2237=People!$B$5,People!$A$5,IF(M2237=People!$B$4,People!$A$4,IF(M2237=People!$B$3,People!$A$3,IF(M2237=People!$B$2,People!$A$2,0)))) -> Kelly Williams | W2237: =IFERROR(INDEX(Returns!A:A,MATCH(B2237,Returns!B:B,0)),"No") -> No
A2238: 2237 | B2238: CA-2017-145849 | C2238: 42993 | D2238: 42995 | E2238: Second Class | F2238: CT-11995 | G2238: Carol Triggs | H2238: Consumer | I2238: United States | J2238: Indianapolis | K2238: Indiana | L2238: 46203 | M2238: Central | N2238: OFF-AR-10000817 | O2238: Office Supplies | P2238: Art | Q2238: Manco Dry-Lighter Erasable Highlighter | R2238: 24.32 | S2238: 8 | T2238: 0 | U2238: 8.2688 | V2238: =IF(M2238=People!$B$5,People!$A$5,IF(M2238=People!$B$4,People!$A$4,IF(M2238=People!$B$3,People!$A$3,IF(M2238=People!$B$2,People!$A$2,0)))) -> Kelly Williams | W2238: =IFERROR(INDEX(Returns!A:A,MATCH(B2238,Returns!B:B,0)),"No") -> No
A2239: 2238 | B2239: CA-2018-122322 | C2239: 43296 | D2239: 43302 | E2239: Standard Class | F2239: RH-19510 | G2239: Rick Huthwaite | H2239: Home Office | I2239: United States | J2239: Provo | K2239: Utah | L2239: 84604 | M2239: West | N2239: OFF-SU-10000952 | O2239: Office Supplies | P2239: Supplies | Q2239: Fiskars Home & Office Scissors | R2239: 44.4 | S2239: 5 | T2239: 0 | U2239: 12.432 | V2239: =IF(M2239=People!$B$5,People!$A$5,IF(M2239=People!$B$4,People!$A$4,IF(M2239=People!$B$3,People!$A$3,IF(M2239=People!$B$2,People!$A$2,0)))) -> Anna Andreadi | W2239: =IFERROR(INDEX(Returns!A:A,MATCH(B2239,Returns!B:B,0)),"No") -> No
A2240: 2239 | B2240: CA-2019-166849 | C2240: 43575 | D2240: 43581 | E2240: Standard Class | F2240: SJ-20125 | G2240: Sanjit Jacobs | H2240: Home Office | I2240: United States | J2240: Chicago | K2240: Illinois | L2240: 60610 | M2240: Central | N2240: FUR-FU-10004597 | O2240: Furniture | P2240: Furnishings | Q2240: Eldon Cleatmat Chair Mats for Medium Pile Carpets | R2240: 44.4 | S2240: 2 | T2240: 0.6 | U2240: -52.17 | V2240: =IF(M2240=People!$B$5,People!$A$5,IF(M2240=People!$B$4,People!$A$4,IF(M2240=People!$B$3,People!$A$3,IF(M2240=People!$B$2,People!$A$2,0)))) -> Kelly Williams | W2240: =IFERROR(INDEX(Returns!A:A,MATCH(B2240,Returns!B:B,0)),"No") -> No
A2241: 2240 | B2241: CA-2018-146633 | C2241: 43419 | D2241: 43421 | E2241: Second Class | F2241: TG-21310 | G2241: Toby Gnade | H2241: Consumer | I2241: United States | J2241: Los Angeles | K2241: California | L2241: 90049 | M2241: West | N2241: OFF-BI-10003527 | O2241: Office Supplies | P2241: Binders | Q2241: Fellowes PB500 Electric Punch Plastic Comb Binding Machine with Manual Bind | R2241: 1016.792 | S2241: 1 | T2241: 0.2 | U2241: 381.297 | V2241: =IF(M2241=People!$B$5,People!$A$5,IF(M2241=People!$B$4,People!$A$4,IF(M2241=People!$B$3,People!$A$3,IF(M2241=People!$B$2,People!$A$2,0)))) -> Anna Andreadi | W2241: =IFERROR(INDEX(Returns!A:A,MATCH(B2241,Returns!B:B,0)),"No") -> No
A2242: 2241 | B2242: CA-2018-146633 | C2242: 43419 | D2242: 43421 | E2242: Second Class | F2242: TG-21310 | G2242: Toby Gnade | H2242: Consumer | I2242: United States | J2242: Los Angeles | K2242: California | L2242: 90049 | M2242: West | N2242: OFF-BI-10002982 | O2242: Office Supplies | P2242: Binders | Q2242: Avery Self-Adhesive Photo Pockets for Polaroid Photos | R2242: 38.136 | S2242: 7 | T2242: 0.2 | U2242: 13.3476 | V2242: =IF(M2242=People!$B$5,People!$A$5,IF(M2242=People!$B$4,People!$A$4,IF(M2242=People!$B$3,People!$A$3,IF(M2242=People!$B$2,People!$A$2,0)))) -> Anna Andreadi | W2242: =IFERROR(INDEX(Returns!A:A,MATCH(B2242,Returns!B:B,0)),"No") -> No
A2243: 2242 | B2243: US-2018-126893 | C2243: 43430 | D2243: 43435 | E2243: Standard Class | F2243: CT-11995 | G2243: Carol Triggs | H2243: Consumer | I2243: United States | J2243: Philadelphia | K2243: Pennsylvania | L2243: 19134 | M2243: East | N2243: TEC-PH-10004165 | O2243: Technology | P2243: Phones | Q2243: Mitel MiVoice 5330e IP Phone | R2243: 494.982 | S2243: 3 | T2243: 0.4 | U2243: -115.4958 | V2243: =IF(M2243=People!$B$5,People!$A$5,IF(M2243=People!$B$4,People!$A$4,IF(M2243=People!$B$3,People!$A$3,IF(M2243=People!$B$2,People!$A$2,0)))) -> Chuck Magee | W2243: =IFERROR(INDEX(Returns!A:A,MATCH(B2243,Returns!B:B,0)),"No") -> No
A2244: 2243 | B2244: CA-2019-103380 | C2244: 43790 | D2244: 43794 | E2244: Standard Class | F2244: BF-11005 | G2244: Barry Franz | H2244: Home Office | I2244: United States | J2244: Pasadena | K2244: California | L2244: 91104 | M2244: West | N2244: OFF-ST-10003442 | O2244: Office Supplies | P2244: Storage | Q2244: Eldon Portable Mobile Manager | R2244: 56.56 | S2244: 2 | T2244: 0 | U2244: 15.2712 | V2244: =IF(M2244=People!$B$5,People!$A$5,IF(M2244=People!$B$4,People!$A$4,IF(M2244=People!$B$3,People!$A$3,IF(M2244=People!$B$2,People!$A$2,0)))) -> Anna Andreadi | W2244: =IFERROR(INDEX(Returns!A:A,MATCH(B2244,Returns!B:B,0)),"No") -> Yes
A2245: 2244 | B2245: CA-2019-103380 | C2245: 43790 | D2245: 43794 | E2245: Standard Class | F2245: BF-11005 | G2245: Barry Franz | H2245: Home Office | I2245: United States | J2245: Pasadena | K2245: California | L2245: 91104 | M2245: West | N2245: OFF-AR-10003856 | O2245: Office Supplies | P2245: Art | Q2245: Newell 344 | R2245: 5.56 | S2245: 2 | T2245: 0 | U2245: 1.4456 | V2245: =IF(M2245=People!$B$5,People!$A$5,IF(M2245=People!$B$4,People!$A$4,IF(M2245=People!$B$3,People!$A$3,IF(M2245=People!$B$2,People!$A$2,0)))) -> Anna Andreadi | W2245: =IFERROR(INDEX(Returns!A:A,MATCH(B2245,Returns!B:B,0)),"No") -> Yes
A2246: 2245 | B2246: CA-2019-103380 | C2246: 43790 | D2246: 43794 | E2246: Standard Class | F2246: BF-11005 | G2246: Barry Franz | H2246: Home Office | I2246: United States | J2246: Pasadena | K2246: California | L2246: 91104 | M2246: West | N2246: OFF-FA-10004248 | O2246: Office Supplies | P2246: Fasteners | Q2246: Advantus T-Pin Paper Clips | R2246: 9.02 | S2246: 2 | T2246: 0 | U2246: 3.5178 | V2246: =IF(M2246=People!$B$5,People!$A$5,IF(M2246=People!$B$4,People!$A$4,IF(M2246=People!$B$3,People!$A$3,IF(M2246=People!$B$2,People!$A$2,0)))) -> Anna Andreadi | W2246: =IFERROR(INDEX(Returns!A:A,MATCH(B2246,Returns!B:B,0)),"No") -> Yes
A2247: 2246 | B2247: CA-2019-103380 | C2247: 43790 | D2247: 43794 | E2247: Standard Class | F2247: BF-11005 | G2247: Barry Franz | H2247: Home Office | I2247: United States | J2247: Pasadena | K2247: California | L2247: 91104 | M2247: West | N2247: OFF-AP-10001492 | O2247: Office Supplies | P2247: Appliances | Q2247: Acco Six-Outlet Power Strip, 4' Cord Length | R2247: 8.62 | S2247: 1 | T2247: 0 | U2247: 2.2412 | V2247: =IF(M2247=People!$B$5,People!$A$5,IF(M2247=People!$B$4,People!$A$4,IF(M2247=People!$B$3,People!$A$3,IF(M2247=People!$B$2,People!$A$2,0)))) -> Anna Andreadi | W2247: =IFERROR(INDEX(Returns!A:A,MATCH(B2247,Returns!B:B,0)),"No") -> Yes
A2248: 2247 | B2248: CA-2019-103380 | C2248: 43790 | D2248: 43794 | E2248: Standard Class | F2248: BF-11005 | G2248: Barry Franz | H2248: Home Office | I2248: United States | J2248: Pasadena | K2248: California | L2248: 91104 | M2248: West | N2248: TEC-PH-10004165 | O2248: Technology | P2248: Phones | Q2248: Mitel MiVoice 5330e IP Phone | R2248: 659.976 | S2248: 3 | T2248: 0.2 | U2248: 49.4982 | V2248: =IF(M2248=People!$B$5,People!$A$5,IF(M2248=People!$B$4,People!$A$4,IF(M2248=People!$B$3,People!$A$3,IF(M2248=People!$B$2,People!$A$2,0)))) -> Anna Andreadi | W2248: =IFERROR(INDEX(Returns!A:A,MATCH(B2248,Returns!B:B,0)),"No") -> Yes
... A5275: 5274 | B5275: US-2018-158309 | C5275: 43430 | D5275: 43433 | E5275: First Class | F5275: PA-19060 | G5275: Pete Armstrong | H5275: Home Office | I5275: United States | J5275: Miami | K5275: Florida | L5275: 33142 | M5275: South | N5275: OFF-BI-10000145 | O5275: Office Supplies | P5275: Binders | Q5275: Zipper Ring Binder Pockets | R5275: 3.744 | S5275: 4 | T5275: 0.7 | U5275: -2.6208 | V5275: =IF(M5275=People!$B$5,People!$A$5,IF(M5275=People!$B$4,People!$A$4,IF(M5275=People!$B$3,People!$A$3,IF(M5275=People!$B$2,People!$A$2,0)))) -> Cassandra Brandow | W5275: =IFERROR(INDEX(Returns!A:A,MATCH(B5275,Returns!B:B,0)),"No") -> No
A5276: 5275 | B5276: CA-2017-162887 | C5276: 43046 | D5276: 43048 | E5276: Second Class | F5276: SV-20785 | G5276: Stewart Visinsky | H5276: Consumer | I5276: United States | J5276: Burlington | K5276: Vermont | M5276: East | N5276: FUR-CH-10000595 | O5276: Furniture | P5276: Chairs | Q5276: Safco Contoured Stacking Chairs | R5276: 715.2 | S5276: 3 | T5276: 0 | U5276: 178.8 | V5276: =IF(M5276=People!$B$5,People!$A$5,IF(M5276=People!$B$4,People!$A$4,IF(M5276=People!$B$3,People!$A$3,IF(M5276=People!$B$2,People!$A$2,0)))) -> Chuck Magee | W5276: =IFERROR(INDEX(Returns!A:A,MATCH(B5276,Returns!B:B,0)),"No") -> No
A5277: 5276 | B5277: CA-2019-147333 | C5277: 43813 | D5277: 43819 | E5277: Standard Class | F5277: KL-16555 | G5277: Kelly Lampkin | H5277: Corporate | I5277: United States | J5277: Fayetteville | K5277: Arkansas | L5277: 72701 | M5277: South | N5277: TEC-AC-10004469 | O5277: Technology | P5277: Accessories | Q5277: Microsoft Sculpt Comfort Mouse | R5277: 159.8 | S5277: 4 | T5277: 0 | U5277: 70.312 | V5277: =IF(M5277=People!$B$5,People!$A$5,IF(M5277=People!$B$4,People!$A$4,IF(M5277=People!$B$3,People!$A$3,IF(M5277=People!$B$2,People!$A$2,0)))) -> Cassandra Brandow | W5277: =IFERROR(INDEX(Returns!A:A,MATCH(B5277,Returns!B:B,0)),"No") -> No
A5278: 5277 | B5278: CA-2019-147333 | C5278: 43813 | D5278: 43819 | E5278: Standard Class | F5278: KL-16555 | G5278: Kelly Lampkin | H5278: Corporate | I5278: United States | J5278: Fayetteville | K5278: Arkansas | L5278: 72701 | M5278: South | N5278: TEC-AC-10003038 | O5278: Technology | P5278: Accessories | Q5278: Kingston Digital DataTraveler 16GB USB 2.0 | R5278: 44.75 | S5278: 5 | T5278: 0 | U5278: 8.5025 | V5278: =IF(M5278=People!$B$5,People!$A$5,IF(M5278=People!$B$4,People!$A$4,IF(M5278=People!$B$3,People!$A$3,IF(M5278=People!$B$2,People!$A$2,0)))) -> Cassandra Brandow | W5278: =IFERROR(INDEX(Returns!A:A,MATCH(B5278,Returns!B:B,0)),"No") -> No
A5279: 5278 | B5279: CA-2016-113859 | C5279: 42626 | D5279: 42630 | E5279: Standard Class | F5279: BC-11125 | G5279: Becky Castell | H5279: Home Office | I5279: United States | J5279: Odessa | K5279: Texas | L5279: 79762 | M5279: Central | N5279: FUR-CH-10004698 | O5279: Furniture | P5279: Chairs | Q5279: Padded Folding Chairs, Black, 4/Carton | R5279: 340.116 | S5279: 6 | T5279: 0.3 | U5279: -9.7176 | V5279: =IF(M5279=People!$B$5,People!$A$5,IF(M5279=People!$B$4,People!$A$4,IF(M5279=People!$B$3,People!$A$3,IF(M5279=People!$B$2,People!$A$2,0)))) -> Kelly Williams | W5279: =IFERROR(INDEX(Returns!A:A,MATCH(B5279,Returns!B:B,0)),"No") -> No
A5280: 5279 | B5280: CA-2016-159681 | C5280: 42711 | D5280: 42717 | E5280: Standard Class | F5280: PO-18850 | G5280: Patrick O'Brill | H5280: Consumer | I5280: United States | J5280: Virginia Beach | K5280: Virginia | L5280: 23464 | M5280: South | N5280: OFF-PA-10003641 | O5280: Office Supplies | P5280: Paper | Q5280: Xerox 1909 | R5280: 105.52 | S5280: 4 | T5280: 0 | U5280: 48.5392 | V5280: =IF(M5280=People!$B$5,People!$A$5,IF(M5280=People!$B$4,People!$A$4,IF(M5280=People!$B$3,People!$A$3,IF(M5280=People!$B$2,People!$A$2,0)))) -> Cassandra Brandow | W5280: =IFERROR(INDEX(Returns!A:A,MATCH(B5280,Returns!B:B,0)),"No") -> No
A5281: 5280 | B5281: US-2019-104094 | C5281: 43715 | D5281: 43719 | E5281: Standard Class | F5281: AG-10675 | G5281: Anna Gayman | H5281: Consumer | I5281: United States | J5281: Milwaukee | K5281: Wisconsin | L5281: 53209 | M5281: Central | N5281: TEC-AC-10002134 | O5281: Technology | P5281: Accessories | Q5281: Rosewill 107 Normal Keys USB Wired Standard Keyboard | R5281: 13.48 | S5281: 1 | T5281: 0 | U5281: 1.8872 | V5281: =IF(M5281=People!$B$5,People!$A$5,IF(M5281=People!$B$4,People!$A$4,IF(M5281=People!$B$3,People!$A$3,IF(M5281=People!$B$2,People!$A$2,0)))) -> Kelly Williams | W5281: =IFERROR(INDEX(Returns!A:A,MATCH(B5281,Returns!B:B,0)),"No") -> No
A5282: 5281 | B5282: CA-2019-152709 | C5282: 43745 | D5282: 43750 | E5282: Standard Class | F5282: DB-13210 | G5282: Dean Braden | H5282: Consumer | I5282: United States | J5282: Detroit | K5282: Michigan | L5282: 48234 | M5282: Central | N5282: OFF-ST-10001837 | O5282: Office Supplies | P5282: Storage | Q5282: SAFCO Mobile Desk Side File, Wire Frame | R5282: 85.52 | S5282: 2 | T5282: 0 | U5282: 22.2352 | V5282: =IF(M5282=People!$B$5,People!$A$5,IF(M5282=People!$B$4,People!$A$4,IF(M5282=People!$B$3,People!$A$3,IF(M5282=People!$B$2,People!$A$2,0)))) -> Kelly Williams | W5282: =IFERROR(INDEX(Returns!A:A,MATCH(B5282,Returns!B:B,0)),"No") -> No
A5283: 5282 | B5283: CA-2017-105158 | C5283: 42983 | D5283: 42988 | E5283: Standard Class | F5283: SP-20860 | G5283: Sung Pak | H5283: Corporate | I5283: United States | J5283: Rochester | K5283: Minnesota | L5283: 55901 | M5283: Central | N5283: FUR-FU-10001706 | O5283: Furniture | P5283: Furnishings | Q5283: Longer-Life Soft White Bulbs | R5283: 6.16 | S5283: 2 | T5283: 0 | U5283: 2.9568 | V5283: =IF(M5283=People!$B$5,People!$A$5,IF(M5283=People!$B$4,People!$A$4,IF(M5283=People!$B$3,People!$A$3,IF(M5283=People!$B$2,People!$A$2,0)))) -> Kelly Williams | W5283: =IFERROR(INDEX(Returns!A:A,MATCH(B5283,Returns!B:B,0)),"No") -> Yes
A5284: 5283 | B5284: CA-2017-105158 | C5284: 42983 | D5284: 42988 | E5284: Standard Class | F5284: SP-20860 | G5284: Sung Pak | H5284: Corporate | I5284: United States | J5284: Rochester | K5284: Minnesota | L5284: 55901 | M5284: Central | N5284: OFF-PA-10001970 | O5284: Office Supplies | P5284: Paper | Q5284: Xerox 1881 | R5284: 36.84 | S5284: 3 | T5284: 0 | U5284: 17.3148 | V5284: =IF(M5284=People!$B$5,People!$A$5,IF(M5284=People!$B$4,People!$A$4,IF(M5284=People!$B$3,People!$A$3,IF(M5284=People!$B$2,People!$A$2,0)))) -> Kelly Williams | W5284: =IFERROR(INDEX(Returns!A:A,MATCH(B5284,Returns!B:B,0)),"No") -> Yes
A5285: 5284 | B5285: CA-2016-133424 | C5285: 42459 | D5285: 42464 | E5285: Standard Class | F5285: Dl-13600 | G5285: Dorris liebe | H5285: Corporate | I5285: United States | J5285: Seattle | K5285: Washington | L5285: 98105 | M5285: West | N5285: OFF-ST-10002957 | O5285: Office Supplies | P5285: Storage | Q5285: Sterilite Show Offs Storage Containers | R5285: 15.84 | S5285: 3 | T5285: 0 | U5285: 0 | V5285: =IF(M5285=People!$B$5,People!$A$5,IF(M5285=People!$B$4,People!$A$4,IF(M5285=People!$B$3,People!$A$3,IF(M5285=People!$B$2,People!$A$2,0)))) -> Anna Andreadi | W5285: =IFERROR(INDEX(Returns!A:A,MATCH(B5285,Returns!B:B,0)),"No") -> No
A5286: 5285 | B5286: CA-2016-133424 | C5286: 42459 | D5286: 42464 | E5286: Standard Class | F5286: Dl-13600 | G5286: Dorris liebe | H5286: Corporate | I5286: United States | J5286: Seattle | K5286: Washington | L5286: 98105 | M5286: West | N5286: OFF-LA-10002312 | O5286: Office Supplies | P5286: Labels | Q5286: Avery 490 | R5286: 44.4 | S5286: 3 | T5286: 0 | U5286: 22.2 | V5286: =IF(M5286=People!$B$5,People!$A$5,IF(M5286=People!$B$4,People!$A$4,IF(M5286=People!$B$3,People!$A$3,IF(M5286=People!$B$2,People!$A$2,0)))) -> Anna Andreadi | W5286: =IFERROR(INDEX(Returns!A:A,MATCH(B5286,Returns!B:B,0)),"No") -> No
A5287: 5286 | B5287: CA-2019-105991 | C5287: 43590 | D5287: 43591 | E5287: First Class | F5287: LH-17020 | G5287: Lisa Hazard | H5287: Consumer | I5287: United States | J5287: Louisville | K5287: Colorado | L5287: 80027 | M5287: West | N5287: OFF-EN-10002600 | O5287: Office Supplies | P5287: Envelopes | Q5287: Redi-Strip #10 Envelopes, 4 1/8 x 9 1/2 | R5287: 21.24 | S5287: 9 | T5287: 0.2 | U5287: 7.434 | V5287: =IF(M5287=People!$B$5,People!$A$5,IF(M5287=People!$B$4,People!$A$4,IF(M5287=People!$B$3,People!$A$3,IF(M5287=People!$B$2,People!$A$2,0)))) -> Anna Andreadi | W5287: =IFERROR(INDEX(Returns!A:A,MATCH(B5287,Returns!B:B,0)),"No") -> No
...

Sheet People
A1: Person | B1: Region
A2: Anna Andreadi | B2: West
A3: Chuck Magee | B3: East
A4: Kelly Williams | B4: Central
A5: Cassandra Brandow | B5: South

Sheet Returns
A1: Returned | B1: Order ID
A2: Yes | B2: CA-2016-100762
A3: Yes | B3: CA-2016-100762
A4: Yes | B4: CA-2016-100762
A5: Yes | B5: CA-2016-100762
A6: Yes | B6: CA-2016-100867
A7: Yes | B7: CA-2016-102652
A8: Yes | B8: CA-2016-102652
A9: Yes | B9: CA-2016-102652
A10: Yes | B10: CA-2016-102652
A11: Yes | B11: CA-2016-103373
A12: Yes | B12: CA-2016-103744
... A801: Yes | B801: US-2019-155999

Sheet Postal Code Unique Customers
A3: Названия строк | B3: Число разных элементов в столбце Customer ID
A4: 10035 | B4: 118
A5: 10024 | B5: 115
A6: 10009 | B6: 105
A7: 94122 | B7: 95
A8: 10011 | B8: 92
A9: 94110 | B9: 82
A10: 94109 | B10: 78
A11: 98105 | B11: 74
A12: 98103 | B12: 72
A13: 19140 | B13: 69
A14: Общий итог | B14: 568

Sheet Profit by Postal code
A3: Названия строк | B3: Сумма по столбцу Profit
A4: 10024 | B4: 21653.725
A5: 10035 | B5: 16533.867 | D5: 1040 | E5: =D5 &"-0000" -> 1040-0000 | F5: 60.392
A6: 10009 | B6: 13697.002 | D6: 1453 | E6: =D6 &"-0000" -> 1453-0000 | F6: 79.5016
A7: 98115 | B7: 13303.875 | D7: 1752 | E7: =D7 &"-0000" -> 1752-0000 | F7: 67.6068
A8: 10011 | B8: 10152.39 | D8: 1810 | E8: =D8 &"-0000" -> 1810-0000 | F8: 124.1886
A9: 47905 | B9: 8976.0973 | D9: 1841 | E9: =D9 &"-0000" -> 1841-0000 | F9: 1849.4035
A10: 98105 | B10: 8734.6042 | D10: 1852 | E10: =D10 &"-0000" -> 1852-0000 | F10: 1312.5717
A11: 19711 | B11: 8086.1715 | D11: 1915 | E11: =D11 &"-0000" -> 1915-0000 | F11: 654.9194
A12: 48205 | B12: 7994.5263 | D12: 2038 | E12: =D12 &"-0000" -> 2038-0000 | F12: 464.6287
A13: 90049 | B13: 7793.1145 | D13: 2138 | E13: =D13 &"-0000" -> 2138-0000 | F13: 173.7276
A14: 94122 | B14: 7712.5958 | D14: 2148 | E14: =D14 &"-0000" -> 2148-0000 | F14: 31.1692
A15: 98103 | B15: 7117.617 | D15: 2149 | E15: =D15 &"-0000" -> 2149-0000 | F15: 1360.0809
A16: 30318 | B16: 6993.6629 | D16: 2151 | E16: =D16 &"-0000" -> 2151-0000 | F16: 258.8366
... A44: 89031 | B44: 2247.6899 | D44: 7060 | E44: =D44 &"-0000" -> 7060-0000 | F44: 1235.6657
A45: (пусто) | B45: 2244.9783 | D45: 7090 | E45: =D45 &"-0000" -> 7090-0000 | F45: 153.1758
A46: 36608 | B46: 2175.8292 | D46: 7109 | E46: =D46 &"-0000" -> 7109-0000 | F46: 283.6492
A47: 39212 | B47: 2100.4405 | D47: 7501 | E47: =D47 &"-0000" -> 7501-0000 | F47: 740.49
A48: 95823 | B48: 2069.6859 | D48: 7601 | E48: =D48 &"-0000" -> 7601-0000 | F48: 451.2547
A49: 23464 | B49: 2024.8837 | D49: 7960 | E49: =D49 &"-0000" -> 7960-0000 | F49: 1838.2271
A50: 40214 | B50: 1975.8966 | D50: 8302 | E50: =D50 &"-0000" -> 8302-0000 | F50: 3.4416
A51: 47374 | B51: 1881.862 | D51: 8360 | E51: =D51 &"-0000" -> 8360-0000 | F51: 62.2518
A52: 1841 | B52: 1849.4035 | D52: 8401 | E52: =D52 &"-0000" -> 8401-0000 | F52: 11.68
A53: 68104 | B53: 1841.6268 | D53: 8701 | E53: =D53 &"-0000" -> 8701-0000 | F53: 3526.6735
A54: 7960 | B54: 1838.2271 | D54: 8861 | E54: =D54 &"-0000" -> 8861-0000 | F54: 633.644
A55: 41042 | B55: 1837.3541 | D55: 8901 | E55: =D55 &"-0000" -> 8901-0000 | F55: 7.1567
A56: 92105 | B56: 1789.4906 | D56: 10009 | E56: =D56 &"-0000" -> 10009-0000 | F56: 13697.002
A57: 19805 | B57: 1775.0723 | D57: 10011 | E57: =D57 &"-0000" -> 10011-0000 | F57: 10152.39
... A634: 78207 | B634: -7299.0502 | D634: 99301 | E634: =D634 &"-0000" -> 99301-0000 | F634: 357.5244
A635: Общий итог | B635: 286397.02

Sheet Динамика дохода и прибыли
B3: Данные
A4: Названия строк | B4: Сумма по полю Sales | C4: Сумма по полю Profit
A5: 2016
A6: янв | B6: 14236.895 | C6: 2450.1907
A7: фев | B7: 4519.892 | C7: 862.3084
A8: мар | B8: 55691.009 | C8: 498.7299
A9: апр | B9: 28295.345 | C9: 3488.8352
A10: май | B10: 23648.287 | C10: 2738.7096
A11: июн | B11: 34595.128 | C11: 4976.5244
A12: июл | B12: 33946.393 | C12: -841.4826
A13: авг | B13: 27909.468 | C13: 5318.105
A14: сен | B14: 81777.351 | C14: 8328.0994
A15: окт | B15: 31453.393 | C15: 3448.2573
A16: ноя | B16: 78628.717 | C16: 9292.1269
A17: дек | B17: 69545.62 | C17: 8983.5699
A18: 2017
A19: янв | B19: 18174.076 | C19: -3281.007
A20: фев | B20: 11951.411 | C20: 2813.8508
A21: мар | B21: 38726.252 | C21: 9732.0978
A22: апр | B22: 34195.208 | C22: 4187.4962
A23: май | B23: 30131.686 | C23: 4667.869
A24: июн | B24: 24797.292 | C24: 3335.5572
A25: июл | B25: 28765.325 | C25: 3288.6483
A26: авг | B26: 36898.332 | C26: 5355.8084
A27: сен | B27: 64595.918 | C27: 8209.1627
A28: окт | B28: 31404.924 | C28: 2817.366
A29: ноя | B29: 75972.564 | C29: 12474.788
A30: дек | B30: 74919.521 | C30: 8016.9659
A31: 2018
A32: янв | B32: 18542.491 | C32: 2824.8233
A33: фев | B33: 22978.815 | C33: 5004.5795
A34: мар | B34: 51715.875 | C34: 3611.968
A35: апр | B35: 38750.039 | C35: 2977.8149
A36: май | B36: 56987.728 | C36: 8662.1464
A37: июн | B37: 40344.534 | C37: 4750.3781
A38: июл | B38: 39261.963 | C38: 4432.8779
A39: авг | B39: 31115.374 | C39: 2062.0693
A40: сен | B40: 73410.025 | C40: 9328.6576
A41: окт | B41: 59687.745 | C41: 16243.143
A42: ноя | B42: 79411.966 | C42: 4011.4075
...

Sheet Sales by Category
A3: Названия строк | B3: Сумма по столбцу Sales
A4: Furniture | B4: 741999.8
A5: Office Supplies | B5: 719047.03
A6: Technology | B6: 836154.03
A7: Общий итог | B7: 2297200.9

Sheet Sales by Segment
A3: Названия строк | B3: Сумма по столбцу Sales
A4: Consumer | B4: 1161401.3
A5: Corporate | B5: 706146.37
A6: Home Office | B6: 429653.15
A7: Общий итог | B7: 2297200.9

Sheet Monthly Sales Segment
A2: Region | B2: (Все)
A4: Сумма по полю Sales | C4: Segment
A5: Годы | B5: Order Date | C5: Consumer | D5: Corporate | E5: Home Office | F5: Общий итог
A6: 2016 | B6: янв | C6: 6927.817 | D6: 1701.528 | E6: 5607.55 | F6: 14236.895
B7: фев | C7: 3167.854 | D7: 1183.668 | E7: 168.37 | F7: 4519.892
B8: мар | C8: 11869.304 | D8: 11106.799 | E8: 32714.906 | F8: 55691.009
B9: апр | C9: 9108.612 | D9: 14131.729 | E9: 5055.004 | F9: 28295.345
B10: май | C10: 12819.163 | D10: 9142 | E10: 1687.124 | F10: 23648.287
B11: июн | C11: 25923.748 | D11: 3970.914 | E11: 4700.466 | F11: 34595.128
B12: июл | C12: 20197.74 | D12: 10032.988 | E12: 3715.665 | F12: 33946.393
B13: авг | C13: 16215.263 | D13: 7451.774 | E13: 4242.431 | F13: 27909.468
B14: сен | C14: 59690.65 | D14: 15507.745 | E14: 6578.9558 | F14: 81777.351
B15: окт | C15: 16246.697 | D15: 12637.678 | E15: 2569.018 | F15: 31453.393
B16: ноя | C16: 46571.978 | D16: 20994.495 | E16: 11062.244 | F16: 78628.717
B17: дек | C17: 37357.986 | D17: 20573.556 | E17: 11614.078 | F17: 69545.62
A18: 2017 | B18: янв | C18: 14274.984 | D18: 3382.464 | E18: 516.628 | F18: 18174.076
B19: фев | C19: 9269.018 | D19: 2565.257 | E19: 117.136 | F19: 11951.411
B20: мар | C20: 17418.89 | D20: 16332.018 | E20: 4975.3436 | F20: 38726.252
B21: апр | C21: 22626.405 | D21: 4121.044 | E21: 7447.759 | F21: 34195.208
B22: май | C22: 20879.179 | D22: 5454.9395 | E22: 3797.568 | F22: 30131.686
B23: июн | C23: 12824.504 | D23: 9404.089 | E23: 2568.699 | F23: 24797.292
B24: июл | C24: 19948.813 | D24: 7191.7 | E24: 1624.812 | F24: 28765.325
B25: авг | C25: 20589.835 | D25: 11455.759 | E25: 4852.738 | F25: 36898.332
B26: сен | C26: 38860.273 | D26: 16604.561 | E26: 9131.084 | F26: 64595.918
B27: окт | C27: 17128.868 | D27: 8646.369 | E27: 5629.686 | F27: 31404.923
B28: ноя | C28: 33146.833 | D28: 27299.645 | E28: 15526.086 | F28: 75972.563
B29: дек | C29: 39568.331 | D29: 16299.461 | E29: 19051.729 | F29: 74919.521
A30: 2018 | B30: янв | C30: 6026.649 | D30: 9485.124 | E30: 3030.718 | F30: 18542.491
B31: фев | C31: 15800.227 | D31: 2866.884 | E31: 4311.704 | F31: 22978.815
B32: мар | C32: 24844.991 | D32: 14226.473 | E32: 12644.411 | F32: 51715.875
B33: апр | C33: 14075.248 | D33: 16177.376 | E33: 8497.415 | F33: 38750.039
B34: май | C34: 32174.635 | D34: 18452.258 | E34: 6360.835 | F34: 56987.728
B35: июн | C35: 23888.811 | D35: 7788.494 | E35: 8667.229 | F35: 40344.534
B36: июл | C36: 22631.847 | D36: 13168.919 | E36: 3461.197 | F36: 39261.963
B37: авг | C37: 13885.564 | D37: 12943.471 | E37: 4286.34 | F37: 31115.374
B38: сен | C38: 42647.794 | D38: 17802.812 | E38: 12959.419 | F38: 73410.025
B39: окт | C39: 10143.282 | D39: 32130.545 | E39: 17413.918 | F39: 59687.745
B40: ноя | C40: 41449.863 | D40: 26493.18 | E40: 11468.923 | F40: 79411.966
B41: дек | C41: 49294.989 | D41: 35570.826 | E41: 12133.228 | F41: 96999.043
A42: 2019 | B42: янв | C42: 23211.841 | D42: 12221.232 | E42: 8538.301 | F42: 43971.374
...

Sheet Monthly Sales Product Category
A1: Region | B1: (Все)
A3: Сумма по полю Sales | C3: Category
A4: Годы | B4: Order Date | C4: Furniture | D4: Office Supplies | E4: Technology | F4: Общий итог
A5: 2016 | B5: янв | C5: 6242.525 | D5: 4851.08 | E5: 3143.29 | F5: 14236.895
B6: фев | C6: 1839.658 | D6: 1071.724 | E6: 1608.51 | F6: 4519.892
B7: мар | C7: 14573.956 | D7: 8605.879 | E7: 32511.174 | F7: 55691.009
B8: апр | C8: 7944.837 | D8: 11155.074 | E8: 9195.434 | F8: 28295.345
B9: май | C9: 6912.787 | D9: 7135.624 | E9: 9599.876 | F9: 23648.287
B10: июн | C10: 13206.126 | D10: 12953.037 | E10: 8435.965 | F10: 34595.128
B11: июл | C11: 10821.051 | D11: 15121.208 | E11: 8004.134 | F11: 33946.393
B12: авг | C12: 7320.3465 | D12: 11379.462 | E12: 9209.66 | F12: 27909.469
B13: сен | C13: 23816.481 | D13: 27423.298 | E13: 30537.572 | F13: 81777.351
B14: окт | C14: 12304.247 | D14: 7211.128 | E14: 11938.018 | F14: 31453.393
B15: ноя | C15: 21564.873 | D15: 26862.436 | E15: 30201.408 | F15: 78628.717
B16: дек | C16: 30645.967 | D16: 18006.462 | E16: 20893.192 | F16: 69545.621
A17: 2016 Итог | C17: 157192.85 | D17: 151776.41 | E17: 175278.23 | F17: 484247.5
A18: 2017 | B18: янв | C18: 11739.942 | D18: 1808.78 | E18: 4625.354 | F18: 18174.076
B19: фев | C19: 3134.374 | D19: 5368.067 | E19: 3448.97 | F19: 11951.411
B20: мар | C20: 12499.783 | D20: 15882.547 | E20: 10343.922 | F20: 38726.252
B21: апр | C21: 10475.698 | D21: 12558.558 | E21: 11160.952 | F21: 34195.209
B22: май | C22: 9374.9505 | D22: 9113.736 | E22: 11643 | F22: 30131.687
B23: июн | C23: 7714.179 | D23: 10647.747 | E23: 6435.366 | F23: 24797.292
B24: июл | C24: 13674.42 | D24: 4719.939 | E24: 10370.966 | F24: 28765.325
B25: авг | C25: 9638.5922 | D25: 11735.108 | E25: 15524.632 | F25: 36898.332
B26: сен | C26: 26273.023 | D26: 19305.767 | E26: 19017.128 | F26: 64595.918
B27: окт | C27: 12026.624 | D27: 8673.41 | E27: 10704.89 | F27: 31404.923
B28: ноя | C28: 30880.832 | D28: 21218.13 | E28: 23873.601 | F28: 75972.563
B29: дек | C29: 23085.819 | D29: 16201.674 | E29: 35632.028 | F29: 74919.521
A30: 2017 Итог | C30: 170518.24 | D30: 137233.46 | E30: 162780.81 | F30: 470532.51
A31: 2018 | B31: янв | C31: 7622.743 | D31: 5299.682 | E31: 5620.066 | F31: 18542.491
B32: фев | C32: 3925.551 | D32: 6794.35 | E32: 12258.914 | F32: 22978.815
B33: мар | C33: 12801.092 | D33: 17346.931 | E33: 21567.852 | F33: 51715.875
B34: апр | C34: 13212.09 | D34: 10647.447 | E34: 14890.502 | F34: 38750.039
B35: май | C35: 15119.835 | D35: 13035.202 | E35: 28832.691 | F35: 56987.728
B36: июн | C36: 13070.572 | D36: 10901.81 | E36: 16372.152 | F36: 40344.534
B37: июл | C37: 13068.519 | D37: 12924.444 | E37: 13269 | F37: 39261.963
B38: авг | C38: 12483.232 | D38: 8959.74 | E38: 9672.402 | F38: 31115.374
B39: сен | C39: 27262.881 | D39: 23263.738 | E39: 22883.406 | F39: 73410.025
B40: окт | C40: 11872.577 | D40: 16281.794 | E40: 31533.374 | F40: 59687.745
B41: ноя | C41: 31783.629 | D41: 20487.278 | E41: 27141.059 | F41: 79411.966
...

Sheet Customer Ranking
A1: Segment | B1: (Все)
A2: Region | B2: (Все)
A4: Сумма по полю Sales
A5: Customer Name | B5: Итог
A6: Sean Miller | B6: 25043.05
A7: Tamara Chand | B7: 19052.218
A8: Raymond Buch | B8: 15117.339
A9: Tom Ashbrook | B9: 14595.62
A10: Adrian Barton | B10: 14473.571
A11: Ken Lonsdale | B11: 14175.229
A12: Sanjit Chand | B12: 14142.334
A13: Hunter Lopez | B13: 12873.298
A14: Sanjit Engle | B14: 12209.438
A15: Christopher Conant | B15: 12129.072
A16: Общий итог | B16: 153811.17

Sheet Profit by State
A3: Названия строк | B3: Сумма по столбцу Profit
A4: Alabama | B4: 5786.8253
A5: Arizona | B5: -3427.9246
A6: Arkansas | B6: 4008.6871
A7: California | B7: 76381.387
A8: Colorado | B8: -6527.8579
A9: Connecticut | B9: 3511.4918
A10: Delaware | B10: 9977.3748
A11: District of Columbia | B11: 1059.5893
A12: Florida | B12: -3399.3017
A13: Georgia | B13: 16250.043
A14: Idaho | B14: 826.7231
A15: Illinois | B15: -12607.887
... A53: Общий итог | B53: 286397.02
C185: Alabama | D185: 5786.8253
C186: Arizona | D186: -3427.9246
C187: Arkansas | D187: 4008.6871
C188: California | D188: 76381.387
C189: Colorado | D189: -6527.8579
C190: Connecticut | D190: 3511.4918
C191: Delaware | D191: 9977.3748
C192: District of Columbia | D192: 1059.5893
C193: Florida | D193: -3399.3017
C194: Georgia | D194: 16250.043
C195: Idaho | D195: 826.7231
C196: Illinois | D196: -12607.887
... C233: Wyoming | D233: 100.196
